<?xml version='1.0'?>
<sdf version='1.4'>
    <model name="arm_robot">
        <static>false</static>
        <self_collide>1</self_collide>
        <link name='base'>
            <pose>0 0 .05 0 0 0</pose>
            <inertial>
                <mass>50.0</mass>
            </inertial>
            <collision name='collision'>
                <geometry>
                    <cylinder>
                        <radius>.5</radius>
                        <length>.1</length>
                    </cylinder>
                </geometry>
            </collision>

            <visual name='visual'>
                <geometry>
                    <cylinder>
                        <radius>.5</radius>
                        <length>.1</length>
                    </cylinder>
                </geometry>
            </visual>
        </link>
        <link name='arm1'>
            <pose>0 0 .125 0 0 0</pose>
            <inertial>
                <mass>.05</mass>
            </inertial>
            <collision name='collision'>
                <geometry>
                    <cylinder>
                        <radius>.1</radius>
                        <length>.05</length>
                    </cylinder>
                </geometry>
            </collision>

            <visual name='visual'>
                <geometry>
                    <cylinder>
                        <radius>.1</radius>
                        <length>.05</length>
                    </cylinder>
                </geometry>
            </visual>
        </link>

        <joint type="revolute" name="base_arm1_joint">
            <pose>0 0 -0.025 0 0 0</pose>
            <child>arm1</child>
            <parent>base</parent>
            <axis>
                <xyz>0 0 1</xyz>
                <dynamics>
                    <damping>
                        2.0
                    </damping>
                    <friction>
                        0.7
                    </friction>              
                </dynamics>
                <limit>
                    <effort>100</effort>
                    <velocity>1.0</velocity>
                </limit>
            </axis>
        </joint>

        <link name='arm2'>
            <pose>0 0 1.15 0 0 0</pose>
            <inertial>
                <mass>1.0</mass>
            </inertial>
            <collision name='collision'>
                <geometry>
                    <cylinder>
                        <radius>.05</radius>
                        <length>2.0</length>
                    </cylinder>
                </geometry>
            </collision>

            <visual name='visual'>
                <geometry>
                    <cylinder>
                        <radius>.05</radius>
                        <length>2.0</length>
                    </cylinder>
                </geometry>
            </visual>
        </link>
        
         <joint type="revolute" name="arm1_arm2_joint">
            <pose>0 0 -1 0 0 0</pose>
            <child>arm2</child>
            <parent>arm1</parent>
            <axis>
                <xyz>1 0 0</xyz>
                <limit>
                        <lower>-1.0</lower>
                        <upper>1.0</upper>
                        <effort>100</effort>
                        <velocity>1.0</velocity>
                </limit>           
                <dynamics>
                    <damping>
                        1.0
                    </damping>
                    <friction>
                        0.3
                    </friction>              
                </dynamics>
            </axis>
        </joint>

        <link name='arm3'>
            <pose>0 0 2.65 0 0 0</pose>
            <inertial>
                <mass>0.5</mass>
            </inertial>
            <collision name='collision'>
                <geometry>
                    <cylinder>
                        <radius>.05</radius>
                        <length>1.0</length>
                    </cylinder>
                </geometry>
            </collision>

            <visual name='visual'>
                <geometry>
                    <cylinder>
                        <radius>.05</radius>
                        <length>1.0</length>
                    </cylinder>
                </geometry>
            </visual>
        </link>
        
         <joint type="revolute" name="arm2_arm3_joint">
            <pose>0 0 -0.5 0 0 0</pose>
            <child>arm3</child>
            <parent>arm2</parent>
            <axis>
                <xyz>1 0 0</xyz>
                <dynamics>
                    <damping>
                        1.0
                    </damping>
                    <friction>
                        0.3
                    </friction>              
                </dynamics>
                <limit>
                    <effort>100</effort>
                    <velocity>1.0</velocity>
                </limit>
            </axis>
        </joint>

        <link name='arm4'>
            <pose>0 0 3.4 0 0 0</pose>
            <inertial>
                <mass>.25</mass>
            </inertial>
            <collision name='collision'>
                <geometry>
                    <cylinder>
                        <radius>.05</radius>
                        <length>.5</length>
                    </cylinder>
                </geometry>
            </collision>

            <visual name='visual'>
                <geometry>
                    <cylinder>
                        <radius>.05</radius>
                        <length>.5</length>
                    </cylinder>
                </geometry>
            </visual>
        </link>
        
         <joint type="revolute" name="arm3_arm4_joint">
            <pose>0 0 -0.25 0 0 0</pose>
            <child>arm4</child>
            <parent>arm3</parent>
            <axis>
                <xyz>1 0 0</xyz>
                <dynamics>
                    <damping>
                        1.0
                    </damping>
                    <friction>
                        0.3
                    </friction>              
                </dynamics>
                <limit>
                    <effort>100</effort>
                    <velocity>1.0</velocity>
                </limit>
            </axis>
        </joint>

        <link name="palm">
            <pose>0.0 0.0 3.7 0 0 0</pose>
            <inertial>
                <inertia>
                    <ixx>0.01</ixx>
                    <ixy>0</ixy>
                    <ixz>0</ixz>
                    <iyy>0.01</iyy>
                    <iyz>0</iyz>
                    <izz>0.01</izz>
                </inertia>
                <mass>0.5</mass>
            </inertial>
            <collision name="collision">
                <geometry>
                    <box>
                        <size>0.1 0.2 0.1</size>
                    </box>
                </geometry>
            </collision>
            <visual name="visual">
                <geometry>
                    <box>
                        <size>0.1 0.2 0.1</size>
                    </box>
                </geometry>
                <material>
                    <script>Gazebo/Red</script>
                </material>
            </visual>
        </link>
        <link name="left_finger">
            <pose>0.1 0.2 3.7 0 0 -0.78539</pose>
            <inertial>
                <inertia>
                    <ixx>0.01</ixx>
                    <ixy>0</ixy>
                    <ixz>0</ixz>
                    <iyy>0.01</iyy>
                    <iyz>0</iyz>
                    <izz>0.01</izz>
                </inertia>
                <mass>0.1</mass>
            </inertial>
            <collision name="collision">
                <geometry>
                    <box>
                        <size>0.1 0.3 0.1</size>
                    </box>
                </geometry>
            </collision>
            <visual name="visual">
                <geometry>
                    <box>
                        <size>0.1 0.3 0.1</size>
                    </box>
                </geometry>
                <material>
                    <script>Gazebo/Blue</script>
                </material>
            </visual>
        </link>
        <link name="left_finger_tip">
            <pose>0.336 0.3 3.7 0 0 1.5707</pose>
            <inertial>
                <inertia>
                    <ixx>0.01</ixx>
                    <ixy>0</ixy>
                    <ixz>0</ixz>
                    <iyy>0.01</iyy>
                    <iyz>0</iyz>
                    <izz>0.01</izz>
                </inertia>
                <mass>0.1</mass>
            </inertial>
            <collision name="collision">
                <geometry>
                    <box>
                        <size>0.1 0.2 0.1</size>
                    </box>
                </geometry>
            </collision>
            <visual name="visual">
                <geometry>
                    <box>
                        <size>0.1 0.2 0.1</size>
                    </box>
                </geometry>
                <material>
                    <script>Gazebo/Blue</script>
                </material>
            </visual>
        </link>
        <link name="right_finger">
            <pose>0.1 -0.2 3.7 0 0 .78539</pose>
            <inertial>
                <inertia>
                    <ixx>0.01</ixx>
                    <ixy>0</ixy>
                    <ixz>0</ixz>
                    <iyy>0.01</iyy>
                    <iyz>0</iyz>
                    <izz>0.01</izz>
                </inertia>
                <mass>0.1</mass>
            </inertial>
            <collision name="collision">
                <geometry>
                    <box>
                        <size>0.1 0.3 0.1</size>
                    </box>
                </geometry>
            </collision>
            <visual name="visual">
                <geometry>
                    <box>
                        <size>0.1 0.3 0.1</size>
                    </box>
                </geometry>
                <material>
                    <script>Gazebo/Green</script>
                </material>
            </visual>
        </link>
        <link name="right_finger_tip">
            <pose>0.336 -0.3 3.7 0 0 1.5707</pose>
            <inertial>
                <inertia>
                    <ixx>0.01</ixx>
                    <ixy>0</ixy>
                    <ixz>0</ixz>
                    <iyy>0.01</iyy>
                    <iyz>0</iyz>
                    <izz>0.01</izz>
                </inertia>
                <mass>0.1</mass>
            </inertial>
            <collision name="collision">
                <geometry>
                    <box>
                        <size>0.1 0.2 0.1</size>
                    </box>
                </geometry>
            </collision>
            <visual name="visual">
                <geometry>
                    <box>
                        <size>0.1 0.2 0.1</size>
                    </box>
                </geometry>
                <material>
                    <script>Gazebo/Green</script>
                </material>
            </visual>
        </link>
        <joint name="palm_left_finger" type="revolute">
            <pose>0 -0.15 0 0 0 0</pose>
            <child>left_finger</child>
            <parent>palm</parent>
            <axis>
                <limit>
                    <lower>-0.4</lower>
                    <upper>0.4</upper>
                </limit>
                <xyz>0 0 1</xyz>
            </axis>
        </joint>
        <joint name="left_finger_tip_joint" type="revolute">
            <pose>0 0.1 0 0 0 0</pose>
            <child>left_finger_tip</child>
            <parent>left_finger</parent>
            <axis>
                <limit>
                    <lower>-0.4</lower>
                    <upper>0.4</upper>
                </limit>
                <xyz>0 0 1</xyz>
            </axis>
        </joint>
        <joint name="palm_right_finger" type="revolute">
            <pose>0 0.15 0 0 0 0</pose>
            <child>right_finger</child>
            <parent>palm</parent>
            <axis>
                <limit>
                    <lower>-0.4</lower>
                    <upper>0.4</upper>
                </limit>
                <xyz>0 0 1</xyz>
            </axis>
        </joint>
        <joint name="right_finger_tip_joint" type="revolute">
            <pose>0 0.1 0 0 0 0</pose>
            <child>right_finger_tip</child>
            <parent>right_finger</parent>
            <axis>
                <limit>
                    <lower>-0.4</lower>
                    <upper>0.4</upper>
                </limit>
                <xyz>0 0 1</xyz>
            </axis>
        </joint>
        <joint name="palm_arm4" type="revolute">
            <child>arm4</child>
            <parent>palm</parent>
            <axis>
                <xyz>0 0 1</xyz>
                <dynamics>
                    <damping>1.0</damping>
                    <friction>0.3</friction>
                </dynamics>
                <limit>
                    <lower>0</lower>
                    <upper>0.9</upper>
                </limit>
            </axis>
        </joint>
        <plugin name="arm_control" filename="libarm_gazebo.so" />
    </model>
</sdf>